2018-12-17 15:13:02,461 ERROR: Exception on /user/james [GET] [in /Users/uos/Documents/questionbank/venv/lib/python3.7/site-packages/flask/app.py:1761]
Traceback (most recent call last):
  File "/Users/uos/Documents/questionbank/venv/lib/python3.7/site-packages/flask/app.py", line 2292, in wsgi_app
    response = self.full_dispatch_request()
  File "/Users/uos/Documents/questionbank/venv/lib/python3.7/site-packages/flask/app.py", line 1815, in full_dispatch_request
    rv = self.handle_user_exception(e)
  File "/Users/uos/Documents/questionbank/venv/lib/python3.7/site-packages/flask/app.py", line 1718, in handle_user_exception
    reraise(exc_type, exc_value, tb)
  File "/Users/uos/Documents/questionbank/venv/lib/python3.7/site-packages/flask/_compat.py", line 35, in reraise
    raise value
  File "/Users/uos/Documents/questionbank/venv/lib/python3.7/site-packages/flask/app.py", line 1813, in full_dispatch_request
    rv = self.dispatch_request()
  File "/Users/uos/Documents/questionbank/venv/lib/python3.7/site-packages/flask/app.py", line 1799, in dispatch_request
    return self.view_functions[rule.endpoint](**req.view_args)
  File "/Users/uos/Documents/questionbank/venv/lib/python3.7/site-packages/flask_login/utils.py", line 261, in decorated_view
    return func(*args, **kwargs)
  File "/Users/uos/Documents/questionbank/app/routes.py", line 93, in user
    if questions.has_prev else None
AttributeError: 'Pagination' object has no attribute 'prev_url'
2018-12-17 15:16:09,239 INFO: Questionbank startup [in /Users/uos/Documents/questionbank/app/__init__.py:30]
2018-12-17 15:16:17,192 ERROR: Exception on /user/james [GET] [in /Users/uos/Documents/questionbank/venv/lib/python3.7/site-packages/flask/app.py:1761]
Traceback (most recent call last):
  File "/Users/uos/Documents/questionbank/venv/lib/python3.7/site-packages/flask/app.py", line 2292, in wsgi_app
    response = self.full_dispatch_request()
  File "/Users/uos/Documents/questionbank/venv/lib/python3.7/site-packages/flask/app.py", line 1815, in full_dispatch_request
    rv = self.handle_user_exception(e)
  File "/Users/uos/Documents/questionbank/venv/lib/python3.7/site-packages/flask/app.py", line 1718, in handle_user_exception
    reraise(exc_type, exc_value, tb)
  File "/Users/uos/Documents/questionbank/venv/lib/python3.7/site-packages/flask/_compat.py", line 35, in reraise
    raise value
  File "/Users/uos/Documents/questionbank/venv/lib/python3.7/site-packages/flask/app.py", line 1813, in full_dispatch_request
    rv = self.dispatch_request()
  File "/Users/uos/Documents/questionbank/venv/lib/python3.7/site-packages/flask/app.py", line 1799, in dispatch_request
    return self.view_functions[rule.endpoint](**req.view_args)
  File "/Users/uos/Documents/questionbank/venv/lib/python3.7/site-packages/flask_login/utils.py", line 261, in decorated_view
    return func(*args, **kwargs)
  File "/Users/uos/Documents/questionbank/app/routes.py", line 90, in user
    if questions.has_next else None
AttributeError: 'Pagination' object has no attribute 'next_url'
2018-12-17 15:20:48,612 INFO: Questionbank startup [in /Users/uos/Documents/questionbank/app/__init__.py:30]
2018-12-17 15:23:35,086 INFO: Questionbank startup [in /Users/uos/Documents/questionbank/app/__init__.py:30]
2018-12-17 15:59:31,580 INFO: Questionbank startup [in /Users/uos/Documents/questionbank/app/__init__.py:32]
2018-12-17 16:00:38,607 INFO: Questionbank startup [in /Users/uos/Documents/questionbank/app/__init__.py:32]
2018-12-17 16:19:32,124 INFO: Questionbank startup [in /Users/uos/Documents/questionbank/app/__init__.py:32]
2018-12-17 16:37:06,486 INFO: Questionbank startup [in /Users/uos/Documents/questionbank/app/__init__.py:32]
2018-12-17 16:41:13,104 INFO: Questionbank startup [in /Users/uos/Documents/questionbank/app/__init__.py:32]
2018-12-19 13:52:51,146 INFO: Questionbank startup [in /Users/uos/Documents/questionbank/app/__init__.py:32]
2018-12-19 14:16:45,638 INFO: Questionbank startup [in /Users/uos/Documents/questionbank/app/__init__.py:32]
2018-12-19 14:18:48,397 INFO: Questionbank startup [in /Users/uos/Documents/questionbank/app/__init__.py:32]
2018-12-19 14:38:20,877 INFO: Questionbank startup [in /Users/uos/Documents/questionbank/app/__init__.py:34]
2018-12-19 16:26:10,570 INFO: Questionbank startup [in /Users/uos/Documents/questionbank/app/__init__.py:51]
2018-12-19 16:26:15,314 ERROR: Exception on /index [GET] [in /Users/uos/Documents/questionbank/venv/lib/python3.7/site-packages/flask/app.py:1761]
Traceback (most recent call last):
  File "/Users/uos/Documents/questionbank/venv/lib/python3.7/site-packages/flask/app.py", line 2292, in wsgi_app
    response = self.full_dispatch_request()
  File "/Users/uos/Documents/questionbank/venv/lib/python3.7/site-packages/flask/app.py", line 1815, in full_dispatch_request
    rv = self.handle_user_exception(e)
  File "/Users/uos/Documents/questionbank/venv/lib/python3.7/site-packages/flask/app.py", line 1718, in handle_user_exception
    reraise(exc_type, exc_value, tb)
  File "/Users/uos/Documents/questionbank/venv/lib/python3.7/site-packages/flask/_compat.py", line 35, in reraise
    raise value
  File "/Users/uos/Documents/questionbank/venv/lib/python3.7/site-packages/flask/app.py", line 1813, in full_dispatch_request
    rv = self.dispatch_request()
  File "/Users/uos/Documents/questionbank/venv/lib/python3.7/site-packages/flask/app.py", line 1799, in dispatch_request
    return self.view_functions[rule.endpoint](**req.view_args)
  File "/Users/uos/Documents/questionbank/venv/lib/python3.7/site-packages/flask_login/utils.py", line 261, in decorated_view
    return func(*args, **kwargs)
  File "/Users/uos/Documents/questionbank/app/main/routes.py", line 31, in index
    page, app.config['QUESTIONS_PER_PAGE'], False)
NameError: name 'app' is not defined
2018-12-19 16:26:17,616 ERROR: Exception on /index [GET] [in /Users/uos/Documents/questionbank/venv/lib/python3.7/site-packages/flask/app.py:1761]
Traceback (most recent call last):
  File "/Users/uos/Documents/questionbank/venv/lib/python3.7/site-packages/flask/app.py", line 2292, in wsgi_app
    response = self.full_dispatch_request()
  File "/Users/uos/Documents/questionbank/venv/lib/python3.7/site-packages/flask/app.py", line 1815, in full_dispatch_request
    rv = self.handle_user_exception(e)
  File "/Users/uos/Documents/questionbank/venv/lib/python3.7/site-packages/flask/app.py", line 1718, in handle_user_exception
    reraise(exc_type, exc_value, tb)
  File "/Users/uos/Documents/questionbank/venv/lib/python3.7/site-packages/flask/_compat.py", line 35, in reraise
    raise value
  File "/Users/uos/Documents/questionbank/venv/lib/python3.7/site-packages/flask/app.py", line 1813, in full_dispatch_request
    rv = self.dispatch_request()
  File "/Users/uos/Documents/questionbank/venv/lib/python3.7/site-packages/flask/app.py", line 1799, in dispatch_request
    return self.view_functions[rule.endpoint](**req.view_args)
  File "/Users/uos/Documents/questionbank/venv/lib/python3.7/site-packages/flask_login/utils.py", line 261, in decorated_view
    return func(*args, **kwargs)
  File "/Users/uos/Documents/questionbank/app/main/routes.py", line 31, in index
    page, app.config['QUESTIONS_PER_PAGE'], False)
NameError: name 'app' is not defined
2018-12-19 16:26:44,604 ERROR: Exception on /auth/logout [GET] [in /Users/uos/Documents/questionbank/venv/lib/python3.7/site-packages/flask/app.py:1761]
Traceback (most recent call last):
  File "/Users/uos/Documents/questionbank/venv/lib/python3.7/site-packages/flask/app.py", line 2292, in wsgi_app
    response = self.full_dispatch_request()
  File "/Users/uos/Documents/questionbank/venv/lib/python3.7/site-packages/flask/app.py", line 1815, in full_dispatch_request
    rv = self.handle_user_exception(e)
  File "/Users/uos/Documents/questionbank/venv/lib/python3.7/site-packages/flask/app.py", line 1718, in handle_user_exception
    reraise(exc_type, exc_value, tb)
  File "/Users/uos/Documents/questionbank/venv/lib/python3.7/site-packages/flask/_compat.py", line 35, in reraise
    raise value
  File "/Users/uos/Documents/questionbank/venv/lib/python3.7/site-packages/flask/app.py", line 1813, in full_dispatch_request
    rv = self.dispatch_request()
  File "/Users/uos/Documents/questionbank/venv/lib/python3.7/site-packages/flask/app.py", line 1799, in dispatch_request
    return self.view_functions[rule.endpoint](**req.view_args)
  File "/Users/uos/Documents/questionbank/app/auth/routes.py", line 31, in logout
    return redirect(url_for('index'))
  File "/Users/uos/Documents/questionbank/venv/lib/python3.7/site-packages/flask/helpers.py", line 356, in url_for
    return appctx.app.handle_url_build_error(error, endpoint, values)
  File "/Users/uos/Documents/questionbank/venv/lib/python3.7/site-packages/flask/app.py", line 2061, in handle_url_build_error
    reraise(exc_type, exc_value, tb)
  File "/Users/uos/Documents/questionbank/venv/lib/python3.7/site-packages/flask/_compat.py", line 35, in reraise
    raise value
  File "/Users/uos/Documents/questionbank/venv/lib/python3.7/site-packages/flask/helpers.py", line 345, in url_for
    force_external=external)
  File "/Users/uos/Documents/questionbank/venv/lib/python3.7/site-packages/werkzeug/routing.py", line 1776, in build
    raise BuildError(endpoint, values, method, self)
werkzeug.routing.BuildError: Could not build url for endpoint 'index'. Did you mean 'main.index' instead?
