2018-12-21 11:27:52,627 ERROR: Exception on /search [GET] [in /Users/uos/Documents/questionbank/venv/lib/python3.7/site-packages/flask/app.py:1761]
Traceback (most recent call last):
  File "/Users/uos/Documents/questionbank/venv/lib/python3.7/site-packages/flask/app.py", line 2292, in wsgi_app
    response = self.full_dispatch_request()
  File "/Users/uos/Documents/questionbank/venv/lib/python3.7/site-packages/flask/app.py", line 1815, in full_dispatch_request
    rv = self.handle_user_exception(e)
  File "/Users/uos/Documents/questionbank/venv/lib/python3.7/site-packages/flask/app.py", line 1718, in handle_user_exception
    reraise(exc_type, exc_value, tb)
  File "/Users/uos/Documents/questionbank/venv/lib/python3.7/site-packages/flask/_compat.py", line 35, in reraise
    raise value
  File "/Users/uos/Documents/questionbank/venv/lib/python3.7/site-packages/flask/app.py", line 1813, in full_dispatch_request
    rv = self.dispatch_request()
  File "/Users/uos/Documents/questionbank/venv/lib/python3.7/site-packages/flask/app.py", line 1799, in dispatch_request
    return self.view_functions[rule.endpoint](**req.view_args)
  File "/Users/uos/Documents/questionbank/venv/lib/python3.7/site-packages/flask_login/utils.py", line 261, in decorated_view
    return func(*args, **kwargs)
  File "/Users/uos/Documents/questionbank/app/main/routes.py", line 100, in search
    current_app.config['QUESTIONS_PER_PAGE']
  File "/Users/uos/Documents/questionbank/app/models.py", line 12, in search
    ids, total = query_index(cls.__tablename__, expression, page, per_page)
  File "/Users/uos/Documents/questionbank/app/search.py", line 26, in query_index
    'from': (page - 1) * per_page, 'size': per_page})
  File "/Users/uos/Documents/questionbank/venv/lib/python3.7/site-packages/elasticsearch/client/utils.py", line 76, in _wrapped
    return func(*args, params=params, **kwargs)
  File "/Users/uos/Documents/questionbank/venv/lib/python3.7/site-packages/elasticsearch/client/__init__.py", line 660, in search
    doc_type, '_search'), params=params, body=body)
  File "/Users/uos/Documents/questionbank/venv/lib/python3.7/site-packages/elasticsearch/transport.py", line 318, in perform_request
    status, headers_response, data = connection.perform_request(method, url, params, body, headers=headers, ignore=ignore, timeout=timeout)
  File "/Users/uos/Documents/questionbank/venv/lib/python3.7/site-packages/elasticsearch/connection/http_urllib3.py", line 186, in perform_request
    self._raise_error(response.status, raw_data)
  File "/Users/uos/Documents/questionbank/venv/lib/python3.7/site-packages/elasticsearch/connection/base.py", line 125, in _raise_error
    raise HTTP_EXCEPTIONS.get(status_code, TransportError)(status_code, error_message, additional_info)
elasticsearch.exceptions.NotFoundError: NotFoundError(404, 'index_not_found_exception', 'no such index')
2018-12-21 11:29:42,480 ERROR: Exception on /search [GET] [in /Users/uos/Documents/questionbank/venv/lib/python3.7/site-packages/flask/app.py:1761]
Traceback (most recent call last):
  File "/Users/uos/Documents/questionbank/venv/lib/python3.7/site-packages/flask/app.py", line 2292, in wsgi_app
    response = self.full_dispatch_request()
  File "/Users/uos/Documents/questionbank/venv/lib/python3.7/site-packages/flask/app.py", line 1815, in full_dispatch_request
    rv = self.handle_user_exception(e)
  File "/Users/uos/Documents/questionbank/venv/lib/python3.7/site-packages/flask/app.py", line 1718, in handle_user_exception
    reraise(exc_type, exc_value, tb)
  File "/Users/uos/Documents/questionbank/venv/lib/python3.7/site-packages/flask/_compat.py", line 35, in reraise
    raise value
  File "/Users/uos/Documents/questionbank/venv/lib/python3.7/site-packages/flask/app.py", line 1813, in full_dispatch_request
    rv = self.dispatch_request()
  File "/Users/uos/Documents/questionbank/venv/lib/python3.7/site-packages/flask/app.py", line 1799, in dispatch_request
    return self.view_functions[rule.endpoint](**req.view_args)
  File "/Users/uos/Documents/questionbank/venv/lib/python3.7/site-packages/flask_login/utils.py", line 261, in decorated_view
    return func(*args, **kwargs)
  File "/Users/uos/Documents/questionbank/app/main/routes.py", line 100, in search
    current_app.config['QUESTIONS_PER_PAGE']
  File "/Users/uos/Documents/questionbank/app/models.py", line 12, in search
    ids, total = query_index(cls.__tablename__, expression, page, per_page)
  File "/Users/uos/Documents/questionbank/app/search.py", line 26, in query_index
    'from': (page - 1) * per_page, 'size': per_page})
  File "/Users/uos/Documents/questionbank/venv/lib/python3.7/site-packages/elasticsearch/client/utils.py", line 76, in _wrapped
    return func(*args, params=params, **kwargs)
  File "/Users/uos/Documents/questionbank/venv/lib/python3.7/site-packages/elasticsearch/client/__init__.py", line 660, in search
    doc_type, '_search'), params=params, body=body)
  File "/Users/uos/Documents/questionbank/venv/lib/python3.7/site-packages/elasticsearch/transport.py", line 318, in perform_request
    status, headers_response, data = connection.perform_request(method, url, params, body, headers=headers, ignore=ignore, timeout=timeout)
  File "/Users/uos/Documents/questionbank/venv/lib/python3.7/site-packages/elasticsearch/connection/http_urllib3.py", line 186, in perform_request
    self._raise_error(response.status, raw_data)
  File "/Users/uos/Documents/questionbank/venv/lib/python3.7/site-packages/elasticsearch/connection/base.py", line 125, in _raise_error
    raise HTTP_EXCEPTIONS.get(status_code, TransportError)(status_code, error_message, additional_info)
elasticsearch.exceptions.NotFoundError: NotFoundError(404, 'index_not_found_exception', 'no such index')
2018-12-21 11:35:22,105 INFO: Questionbank startup [in /Users/uos/Documents/questionbank/app/__init__.py:55]
2018-12-21 11:46:03,581 INFO: Questionbank startup [in /Users/uos/Documents/questionbank/app/__init__.py:55]
2018-12-21 11:46:32,595 INFO: Questionbank startup [in /Users/uos/Documents/questionbank/app/__init__.py:55]
